Workbook

Sheet 기록 방법
B1: Utah Devils 경기 기록 v3.0
B2: 노란 칸·파란 글씨: 입력 / 회색·검정 글씨: 계산 / 초록 글씨: 다른 시트 참조
B4: 1. 작성 순서
B5: 1. 경기 정보 입력 → 타자·투수 기록 입력 → 주요 기록 메모
B6: 2. 7–12타석은 타자 기록 V:AA열에 추가 입력
B7: 3. 경기 요약에서 팀 지표와 리뷰 확인
B8: 4. 검수에서 점수·아웃 대조, 입력 누락·판정 확인
B9: 5. 경기 정보에 검수자·완료일 입력 후 3일 이내 시스템 입력
B12: 2. 결과 표기 (기존 16개 + 추가 2개)
B13: 표기 | C13: 의미 | D13: 타수 포함 | F13: 규칙
B14: 안타 | C14: 1루타 (단타) | D14: 포함 | F14: 한 타석 = 한 칸, 한 칸 = 표기 1개.
B15: 2루타 | C15: 2루타 | D15: 포함 | F15: "중전 안타", "우익수 앞" 처럼 방향을
B16: 3루타 | C16: 3루타 | D16: 포함 | F16: 덧붙이지 않는다. 목록의 표기 그대로만.
B17: 홈런 | C17: 홈런 | D17: 포함 | F17: 타점·득점·도루는 표기에 붙이지 않고
B18: 삼진 | C18: 헛스윙 삼진 | D18: 포함 | F18: 오른쪽 전용 칸에 경기 합계로 적는다.
B19: 루킹삼진 | C19: 루킹 삼진 (스탠딩) | D19: 포함 | F19: 타구 방향·메모는 [주요 기록]에만 적는다.
B20: 땅볼 | C20: 땅볼 아웃 | D20: 포함 | F20: 노란 칸 = 사람이 입력
B21: 뜬공 | C21: 뜬공 아웃 (파울플라이 포함) | D21: 포함 | F21: 회색 칸 = 자동 계산 (건드리지 말 것)
B22: 직선타 | C22: 직선타 아웃 | D22: 포함
B23: 병살 | C23: 병살타 | D23: 포함
B24: 실책출루 | C24: 상대 실책으로 출루 | D24: 포함
B25: 야수선택 | C25: 야수선택으로 출루 | D25: 포함
B26: 볼넷 | C26: 볼넷 | D26: 제외
B27: 사구 | C27: 몸에 맞는 공 | D27: 제외
B28: 희생플라이 | C28: 희생플라이 | D28: 제외
B29: 희생번트 | C29: 희생번트 | D29: 제외
B31: 3. 입력 예시 (실제 기록 시트에는 이 행을 넣지 마세요)
B32: 타순 | C32: 이름 | D32: 포지션 | E32: 1타석 | F32: 2타석 | G32: 3타석 | H32: 4타석 | I32: 득점 | J32: 타점 | K32: → 자동계산 결과
B33: 3 | C33: 홍길동 | D33: CF | E33: 2루타 | F33: 볼넷 | G33: 삼진 | H33: 안타 | I33: 2 | J33: 1 | K33: 타수 3 · 안타 2 · 2루타 1 · 볼넷 1 · 삼진 1 · 타율 .667
B35: 4. 파일명 규칙
B36: 자동 계산: AVG·OBP·SLG·OPS / IP·ERA·WHIP·K/BB·K/9·BB/9
B37: 0으로 나눌 수 없는 지표는 n.a. 표시. 기록이 없는 0과 미입력 빈칸 구분.
B39: 5. 검수 기준 (수치 대조·입력 대기·플레이 판정 각각 확인)
B40: 희생플라이는 OBP 분모에 포함. 희생번트·포수방해는 분모에서 제외.
B41: 타율·ERA는 원래 분자·분모로 계산. 화면의 반올림 값으로 재계산하지 않음.
B42: 자책점 미확정은 빈칸 유지. 실책 개수만큼 실점에서 빼는 방식 사용 금지.
B43: 투수 교체 시 잔류 주자의 책임 투수와 교체 시점을 주요 기록에 기재.
B44: 수치 검수 통과와 플레이 판정 확인을 각각 완료. 수정 이유는 검수 이력에 기재.
B46: 기존 입력 좌표 유지. 추가 열·시트 및 확장 타석의 플랫폼 처리 여부는 업로드 전 확인.
B48: 벤치마킹: Wall Street Prep, Financial Modeling Guide (색상·수식 일관성·감사 가능성)
...

Sheet 경기 정보
B1: 경기 정보
B2: 노란 칸만 입력하세요.
B4: 날짜 | C4: =TODAY() -> 46318 | D4: 날짜 형식으로 입력 (예: 2026-09-12)
B5: 상대팀 | C5: 테스트팀 | D5: 파일명에 들어가는 이름과 같게
B6: 홈/원정 | C6: 원정 | D6: 홈 또는 원정
B7: 장소 | C7: 테스트구장
B8: 우리 점수 | C8: 4 | D8: 스코어보드 최종 점수
B9: 상대 점수 | C9: 2 | D9: 스코어보드 최종 점수
B10: 우리 수비 이닝 | C10: 7 | D10: 야구 표기 입력: 7 또는 6.2(6이닝 2아웃). 6.67 입력 금지.
B12: 기록원 A (타자)
B13: 기록원 B (투수)
B14: 1차 검수 (운영팀장)
B15: 2차 검수 (단장·감독)
B16: 검수 완료일
B18: 업로드 파일명 | C18: =IFERROR(MONTH(C4)&"_"&DAY(C4)&" VS "&C5&" 경기 기록","날짜와 상대팀을 먼저 입력하세요") -> 10_23 VS 테스트팀 경기 기록 | D18: 자동 생성. 이 이름으로 파일을 저장한 뒤 업로드하세요 (.xlsx 확장자 포함)
B20: ERA 기준 이닝 | C20: 5 | D20: 공식 비교는 9. 별도 리그 기준 사용 시 변경.
B21: 수비 아웃 기준값 | C21: =IF(NOT(ISNUMBER(C10)),"",ROUND(INT(C10)*3+MOD(C10,1)*10,0)) -> 21 | D21: 스코어북의 수비 이닝을 아웃으로 변환. 투수 합계와 독립 대조.
B22: 시스템 입력 완료일
B23: 검수·입력 마감일 | C23: =IF(NOT(ISNUMBER(C4)),"",C4+3) -> 46321
B24: 마감 준수 | C24: =IF(OR(NOT(ISNUMBER(C16)),NOT(ISNUMBER(C22)),NOT(ISNUMBER(C4))),"완료일 입력 대기",IF(AND(C16>=C4,C22>=C4,MAX(C16,C22)<=C23),"기한 내 완료","기한 초과 또는 날짜 확인")) -> 완료일 입력 대기
B25: 플레이 판정 확인 | D25: 안타·실책·타점·자책점 판정 확인 후 선택.
B26: 교차 기록 대조
B27: 버전 | C27: v3.0 | D27: 기존 시트명·입력 위치 유지. 추가 열의 플랫폼 호환은 업로드 전 확인.

Sheet 타자 기록
A1: 타순 | B1: 이름 | C1: 포지션 | D1: 1타석 | E1: 2타석 | F1: 3타석 | G1: 4타석 | H1: 5타석 | I1: 6타석 | J1: 득점 | K1: 타점 | L1: 도루 | M1: 타수 | N1: 안타 | O1: 2루타 | P1: 3루타 | Q1: 홈런 | R1: 볼넷 | S1: 사구 | T1: 삼진 | U1: 타율 | V1: 7타석 | W1: 8타석 | X1: 9타석 | Y1: 10타석 | Z1: 11타석 | AA1: 12타석 | AB1: 타석 PA | AC1: 희생플라이 | AD1: 희생번트 | AE1: 총루타 TB | AF1: 출루율 OBP | AG1: 장타율 SLG | AH1: OPS | AI1: 포수방해 | AJ1: 병살타 | AK1: 실책출루 | AL1: 야수선택 | AM1: 단타 | AN1: BB% | AO1: K%
A2: 1 | B2: 가선수 | C2: CF | D2: 안타 | E2: 볼넷 | F2: 희생플라이 | G2: 2루타 | J2: 1 | K2: 2 | L2: 1 | M2: =AB2-R2-S2-AC2-AD2-AI2 -> 3 | N2: =SUM(O2:Q2)+AM2 -> 3 | O2: =COUNTIF(D2:I2,"2루타")+COUNTIF(V2:AA2,"2루타") -> 1 | P2: =COUNTIF(D2:I2,"3루타")+COUNTIF(V2:AA2,"3루타") -> 0 | Q2: =COUNTIF(D2:I2,"홈런")+COUNTIF(V2:AA2,"홈런") -> 0 | R2: =COUNTIF(D2:I2,"볼넷")+COUNTIF(V2:AA2,"볼넷") -> 1 | S2: =COUNTIF(D2:I2,"사구")+COUNTIF(V2:AA2,"사구") -> 0 | T2: =COUNTIF(D2:I2,"삼진")+COUNTIF(V2:AA2,"삼진")+COUNTIF(D2:I2,"루킹삼진")+COUNTIF(V2:AA2,"루킹삼진")+COUNTIF(D2:I2,"낫아웃출루")+COUNTIF(V2:AA2,"낫아웃출루") -> 0 | U2: =IF(AB2=0,"",IF(M2=0,"n.a.",N2/M2)) -> 1 | V2: 안타 | AB2: =COUNTA(D2:I2)+COUNTA(V2:AA2) -> 5 | AC2: =COUNTIF(D2:I2,"희생플라이")+COUNTIF(V2:AA2,"희생플라이") -> 1 | AD2: =COUNTIF(D2:I2,"희생번트")+COUNTIF(V2:AA2,"희생번트") -> 0 | AE2: =AM2+2*O2+3*P2+4*Q2 -> 4 | AF2: =IF(AB2=0,"",IF(M2+R2+S2+AC2=0,"n.a.",(N2+R2+S2)/(M2+R2+S2+AC2))) -> 0.8 | AG2: =IF(AB2=0,"",IF(M2=0,"n.a.",AE2/M2)) -> 1.3333333 | AH2: =IF(AB2=0,"",IF(AND(ISNUMBER(AF2),ISNUMBER(AG2)),AF2+AG2,"n.a.")) -> 2.1333333 | AI2: =COUNTIF(D2:I2,"포수방해")+COUNTIF(V2:AA2,"포수방해") -> 0 | AJ2: =COUNTIF(D2:I2,"병살")+COUNTIF(V2:AA2,"병살") -> 0 | AK2: =COUNTIF(D2:I2,"실책출루")+COUNTIF(V2:AA2,"실책출루") -> 0 | AL2: =COUNTIF(D2:I2,"야수선택")+COUNTIF(V2:AA2,"야수선택") -> 0 | AM2: =COUNTIF(D2:I2,"안타")+COUNTIF(V2:AA2,"안타") -> 2 | AN2: =IF(AB2=0,"",R2/AB2) -> 0.2 | AO2: =IF(AB2=0,"",T2/AB2) -> 0
A3: 2 | B3: 나선수 | C3: SS | D3: 삼진 | E3: 루킹삼진 | F3: 낫아웃출루 | G3: 땅볼 | J3: 0 | K3: 0 | L3: 0 | M3: =AB3-R3-S3-AC3-AD3-AI3 -> 4 | N3: =SUM(O3:Q3)+AM3 -> 0 | O3: =COUNTIF(D3:I3,"2루타")+COUNTIF(V3:AA3,"2루타") -> 0 | P3: =COUNTIF(D3:I3,"3루타")+COUNTIF(V3:AA3,"3루타") -> 0 | Q3: =COUNTIF(D3:I3,"홈런")+COUNTIF(V3:AA3,"홈런") -> 0 | R3: =COUNTIF(D3:I3,"볼넷")+COUNTIF(V3:AA3,"볼넷") -> 0 | S3: =COUNTIF(D3:I3,"사구")+COUNTIF(V3:AA3,"사구") -> 0 | T3: =COUNTIF(D3:I3,"삼진")+COUNTIF(V3:AA3,"삼진")+COUNTIF(D3:I3,"루킹삼진")+COUNTIF(V3:AA3,"루킹삼진")+COUNTIF(D3:I3,"낫아웃출루")+COUNTIF(V3:AA3,"낫아웃출루") -> 3 | U3: =IF(AB3=0,"",IF(M3=0,"n.a.",N3/M3)) -> 0 | AB3: =COUNTA(D3:I3)+COUNTA(V3:AA3) -> 4 | AC3: =COUNTIF(D3:I3,"희생플라이")+COUNTIF(V3:AA3,"희생플라이") -> 0 | AD3: =COUNTIF(D3:I3,"희생번트")+COUNTIF(V3:AA3,"희생번트") -> 0 | AE3: =AM3+2*O3+3*P3+4*Q3 -> 0 | AF3: =IF(AB3=0,"",IF(M3+R3+S3+AC3=0,"n.a.",(N3+R3+S3)/(M3+R3+S3+AC3))) -> 0 | AG3: =IF(AB3=0,"",IF(M3=0,"n.a.",AE3/M3)) -> 0 | AH3: =IF(AB3=0,"",IF(AND(ISNUMBER(AF3),ISNUMBER(AG3)),AF3+AG3,"n.a.")) -> 0 | AI3: =COUNTIF(D3:I3,"포수방해")+COUNTIF(V3:AA3,"포수방해") -> 0 | AJ3: =COUNTIF(D3:I3,"병살")+COUNTIF(V3:AA3,"병살") -> 0 | AK3: =COUNTIF(D3:I3,"실책출루")+COUNTIF(V3:AA3,"실책출루") -> 0 | AL3: =COUNTIF(D3:I3,"야수선택")+COUNTIF(V3:AA3,"야수선택") -> 0 | AM3: =COUNTIF(D3:I3,"안타")+COUNTIF(V3:AA3,"안타") -> 0 | AN3: =IF(AB3=0,"",R3/AB3) -> 0 | AO3: =IF(AB3=0,"",T3/AB3) -> 0.75
A4: 3 | B4: 다선수 | C4: 1B | D4: 홈런 | E4: 뜬공 | F4: 사구 | G4: 직선타 | J4: 1 | K4: 1 | L4: 0 | M4: =AB4-R4-S4-AC4-AD4-AI4 -> 3 | N4: =SUM(O4:Q4)+AM4 -> 1 | O4: =COUNTIF(D4:I4,"2루타")+COUNTIF(V4:AA4,"2루타") -> 0 | P4: =COUNTIF(D4:I4,"3루타")+COUNTIF(V4:AA4,"3루타") -> 0 | Q4: =COUNTIF(D4:I4,"홈런")+COUNTIF(V4:AA4,"홈런") -> 1 | R4: =COUNTIF(D4:I4,"볼넷")+COUNTIF(V4:AA4,"볼넷") -> 0 | S4: =COUNTIF(D4:I4,"사구")+COUNTIF(V4:AA4,"사구") -> 1 | T4: =COUNTIF(D4:I4,"삼진")+COUNTIF(V4:AA4,"삼진")+COUNTIF(D4:I4,"루킹삼진")+COUNTIF(V4:AA4,"루킹삼진")+COUNTIF(D4:I4,"낫아웃출루")+COUNTIF(V4:AA4,"낫아웃출루") -> 0 | U4: =IF(AB4=0,"",IF(M4=0,"n.a.",N4/M4)) -> 0.33333333 | AB4: =COUNTA(D4:I4)+COUNTA(V4:AA4) -> 4 | AC4: =COUNTIF(D4:I4,"희생플라이")+COUNTIF(V4:AA4,"희생플라이") -> 0 | AD4: =COUNTIF(D4:I4,"희생번트")+COUNTIF(V4:AA4,"희생번트") -> 0 | AE4: =AM4+2*O4+3*P4+4*Q4 -> 4 | AF4: =IF(AB4=0,"",IF(M4+R4+S4+AC4=0,"n.a.",(N4+R4+S4)/(M4+R4+S4+AC4))) -> 0.5 | AG4: =IF(AB4=0,"",IF(M4=0,"n.a.",AE4/M4)) -> 1.3333333 | AH4: =IF(AB4=0,"",IF(AND(ISNUMBER(AF4),ISNUMBER(AG4)),AF4+AG4,"n.a.")) -> 1.8333333 | AI4: =COUNTIF(D4:I4,"포수방해")+COUNTIF(V4:AA4,"포수방해") -> 0 | AJ4: =COUNTIF(D4:I4,"병살")+COUNTIF(V4:AA4,"병살") -> 0 | AK4: =COUNTIF(D4:I4,"실책출루")+COUNTIF(V4:AA4,"실책출루") -> 0 | AL4: =COUNTIF(D4:I4,"야수선택")+COUNTIF(V4:AA4,"야수선택") -> 0 | AM4: =COUNTIF(D4:I4,"안타")+COUNTIF(V4:AA4,"안타") -> 0 | AN4: =IF(AB4=0,"",R4/AB4) -> 0 | AO4: =IF(AB4=0,"",T4/AB4) -> 0
A5: 4 | B5: 라선수 | C5: C | D5: 희생번트 | E5: 안타 | F5: 병살 | G5: 포수방해 | J5: 0 | K5: 0 | L5: 0 | M5: =AB5-R5-S5-AC5-AD5-AI5 -> 2 | N5: =SUM(O5:Q5)+AM5 -> 1 | O5: =COUNTIF(D5:I5,"2루타")+COUNTIF(V5:AA5,"2루타") -> 0 | P5: =COUNTIF(D5:I5,"3루타")+COUNTIF(V5:AA5,"3루타") -> 0 | Q5: =COUNTIF(D5:I5,"홈런")+COUNTIF(V5:AA5,"홈런") -> 0 | R5: =COUNTIF(D5:I5,"볼넷")+COUNTIF(V5:AA5,"볼넷") -> 0 | S5: =COUNTIF(D5:I5,"사구")+COUNTIF(V5:AA5,"사구") -> 0 | T5: =COUNTIF(D5:I5,"삼진")+COUNTIF(V5:AA5,"삼진")+COUNTIF(D5:I5,"루킹삼진")+COUNTIF(V5:AA5,"루킹삼진")+COUNTIF(D5:I5,"낫아웃출루")+COUNTIF(V5:AA5,"낫아웃출루") -> 0 | U5: =IF(AB5=0,"",IF(M5=0,"n.a.",N5/M5)) -> 0.5 | AB5: =COUNTA(D5:I5)+COUNTA(V5:AA5) -> 4 | AC5: =COUNTIF(D5:I5,"희생플라이")+COUNTIF(V5:AA5,"희생플라이") -> 0 | AD5: =COUNTIF(D5:I5,"희생번트")+COUNTIF(V5:AA5,"희생번트") -> 1 | AE5: =AM5+2*O5+3*P5+4*Q5 -> 1 | AF5: =IF(AB5=0,"",IF(M5+R5+S5+AC5=0,"n.a.",(N5+R5+S5)/(M5+R5+S5+AC5))) -> 0.5 | AG5: =IF(AB5=0,"",IF(M5=0,"n.a.",AE5/M5)) -> 0.5 | AH5: =IF(AB5=0,"",IF(AND(ISNUMBER(AF5),ISNUMBER(AG5)),AF5+AG5,"n.a.")) -> 1 | AI5: =COUNTIF(D5:I5,"포수방해")+COUNTIF(V5:AA5,"포수방해") -> 1 | AJ5: =COUNTIF(D5:I5,"병살")+COUNTIF(V5:AA5,"병살") -> 1 | AK5: =COUNTIF(D5:I5,"실책출루")+COUNTIF(V5:AA5,"실책출루") -> 0 | AL5: =COUNTIF(D5:I5,"야수선택")+COUNTIF(V5:AA5,"야수선택") -> 0 | AM5: =COUNTIF(D5:I5,"안타")+COUNTIF(V5:AA5,"안타") -> 1 | AN5: =IF(AB5=0,"",R5/AB5) -> 0 | AO5: =IF(AB5=0,"",T5/AB5) -> 0
A6: 5 | B6: 마선수 | C6: 3B | D6: 볼넷 | E6: 3루타 | F6: 실책출루 | J6: 1 | K6: 1 | L6: 0 | M6: =AB6-R6-S6-AC6-AD6-AI6 -> 2 | N6: =SUM(O6:Q6)+AM6 -> 1 | O6: =COUNTIF(D6:I6,"2루타")+COUNTIF(V6:AA6,"2루타") -> 0 | P6: =COUNTIF(D6:I6,"3루타")+COUNTIF(V6:AA6,"3루타") -> 1 | Q6: =COUNTIF(D6:I6,"홈런")+COUNTIF(V6:AA6,"홈런") -> 0 | R6: =COUNTIF(D6:I6,"볼넷")+COUNTIF(V6:AA6,"볼넷") -> 1 | S6: =COUNTIF(D6:I6,"사구")+COUNTIF(V6:AA6,"사구") -> 0 | T6: =COUNTIF(D6:I6,"삼진")+COUNTIF(V6:AA6,"삼진")+COUNTIF(D6:I6,"루킹삼진")+COUNTIF(V6:AA6,"루킹삼진")+COUNTIF(D6:I6,"낫아웃출루")+COUNTIF(V6:AA6,"낫아웃출루") -> 0 | U6: =IF(AB6=0,"",IF(M6=0,"n.a.",N6/M6)) -> 0.5 | AB6: =COUNTA(D6:I6)+COUNTA(V6:AA6) -> 3 | AC6: =COUNTIF(D6:I6,"희생플라이")+COUNTIF(V6:AA6,"희생플라이") -> 0 | AD6: =COUNTIF(D6:I6,"희생번트")+COUNTIF(V6:AA6,"희생번트") -> 0 | AE6: =AM6+2*O6+3*P6+4*Q6 -> 3 | AF6: =IF(AB6=0,"",IF(M6+R6+S6+AC6=0,"n.a.",(N6+R6+S6)/(M6+R6+S6+AC6))) -> 0.66666667 | AG6: =IF(AB6=0,"",IF(M6=0,"n.a.",AE6/M6)) -> 1.5 | AH6: =IF(AB6=0,"",IF(AND(ISNUMBER(AF6),ISNUMBER(AG6)),AF6+AG6,"n.a.")) -> 2.1666667 | AI6: =COUNTIF(D6:I6,"포수방해")+COUNTIF(V6:AA6,"포수방해") -> 0 | AJ6: =COUNTIF(D6:I6,"병살")+COUNTIF(V6:AA6,"병살") -> 0 | AK6: =COUNTIF(D6:I6,"실책출루")+COUNTIF(V6:AA6,"실책출루") -> 1 | AL6: =COUNTIF(D6:I6,"야수선택")+COUNTIF(V6:AA6,"야수선택") -> 0 | AM6: =COUNTIF(D6:I6,"안타")+COUNTIF(V6:AA6,"안타") -> 0 | AN6: =IF(AB6=0,"",R6/AB6) -> 0.33333333 | AO6: =IF(AB6=0,"",T6/AB6) -> 0
A7: 6 | B7: 바선수 | C7: LF | D7: 야수선택 | E7: 땅볼 | F7: 안타 | J7: 0 | K7: 0 | L7: 1 | M7: =AB7-R7-S7-AC7-AD7-AI7 -> 3 | N7: =SUM(O7:Q7)+AM7 -> 1 | O7: =COUNTIF(D7:I7,"2루타")+COUNTIF(V7:AA7,"2루타") -> 0 | P7: =COUNTIF(D7:I7,"3루타")+COUNTIF(V7:AA7,"3루타") -> 0 | Q7: =COUNTIF(D7:I7,"홈런")+COUNTIF(V7:AA7,"홈런") -> 0 | R7: =COUNTIF(D7:I7,"볼넷")+COUNTIF(V7:AA7,"볼넷") -> 0 | S7: =COUNTIF(D7:I7,"사구")+COUNTIF(V7:AA7,"사구") -> 0 | T7: =COUNTIF(D7:I7,"삼진")+COUNTIF(V7:AA7,"삼진")+COUNTIF(D7:I7,"루킹삼진")+COUNTIF(V7:AA7,"루킹삼진")+COUNTIF(D7:I7,"낫아웃출루")+COUNTIF(V7:AA7,"낫아웃출루") -> 0 | U7: =IF(AB7=0,"",IF(M7=0,"n.a.",N7/M7)) -> 0.33333333 | AB7: =COUNTA(D7:I7)+COUNTA(V7:AA7) -> 3 | AC7: =COUNTIF(D7:I7,"희생플라이")+COUNTIF(V7:AA7,"희생플라이") -> 0 | AD7: =COUNTIF(D7:I7,"희생번트")+COUNTIF(V7:AA7,"희생번트") -> 0 | AE7: =AM7+2*O7+3*P7+4*Q7 -> 1 | AF7: =IF(AB7=0,"",IF(M7+R7+S7+AC7=0,"n.a.",(N7+R7+S7)/(M7+R7+S7+AC7))) -> 0.33333333 | AG7: =IF(AB7=0,"",IF(M7=0,"n.a.",AE7/M7)) -> 0.33333333 | AH7: =IF(AB7=0,"",IF(AND(ISNUMBER(AF7),ISNUMBER(AG7)),AF7+AG7,"n.a.")) -> 0.66666667 | AI7: =COUNTIF(D7:I7,"포수방해")+COUNTIF(V7:AA7,"포수방해") -> 0 | AJ7: =COUNTIF(D7:I7,"병살")+COUNTIF(V7:AA7,"병살") -> 0 | AK7: =COUNTIF(D7:I7,"실책출루")+COUNTIF(V7:AA7,"실책출루") -> 0 | AL7: =COUNTIF(D7:I7,"야수선택")+COUNTIF(V7:AA7,"야수선택") -> 1 | AM7: =COUNTIF(D7:I7,"안타")+COUNTIF(V7:AA7,"안타") -> 1 | AN7: =IF(AB7=0,"",R7/AB7) -> 0 | AO7: =IF(AB7=0,"",T7/AB7) -> 0
A8: 7 | B8: 사선수 | C8: RF | D8: 뜬공 | E8: 삼진 | F8: 볼넷 | J8: 0 | K8: 0 | L8: 0 | M8: =AB8-R8-S8-AC8-AD8-AI8 -> 2 | N8: =SUM(O8:Q8)+AM8 -> 0 | O8: =COUNTIF(D8:I8,"2루타")+COUNTIF(V8:AA8,"2루타") -> 0 | P8: =COUNTIF(D8:I8,"3루타")+COUNTIF(V8:AA8,"3루타") -> 0 | Q8: =COUNTIF(D8:I8,"홈런")+COUNTIF(V8:AA8,"홈런") -> 0 | R8: =COUNTIF(D8:I8,"볼넷")+COUNTIF(V8:AA8,"볼넷") -> 1 | S8: =COUNTIF(D8:I8,"사구")+COUNTIF(V8:AA8,"사구") -> 0 | T8: =COUNTIF(D8:I8,"삼진")+COUNTIF(V8:AA8,"삼진")+COUNTIF(D8:I8,"루킹삼진")+COUNTIF(V8:AA8,"루킹삼진")+COUNTIF(D8:I8,"낫아웃출루")+COUNTIF(V8:AA8,"낫아웃출루") -> 1 | U8: =IF(AB8=0,"",IF(M8=0,"n.a.",N8/M8)) -> 0 | AB8: =COUNTA(D8:I8)+COUNTA(V8:AA8) -> 3 | AC8: =COUNTIF(D8:I8,"희생플라이")+COUNTIF(V8:AA8,"희생플라이") -> 0 | AD8: =COUNTIF(D8:I8,"희생번트")+COUNTIF(V8:AA8,"희생번트") -> 0 | AE8: =AM8+2*O8+3*P8+4*Q8 -> 0 | AF8: =IF(AB8=0,"",IF(M8+R8+S8+AC8=0,"n.a.",(N8+R8+S8)/(M8+R8+S8+AC8))) -> 0.33333333 | AG8: =IF(AB8=0,"",IF(M8=0,"n.a.",AE8/M8)) -> 0 | AH8: =IF(AB8=0,"",IF(AND(ISNUMBER(AF8),ISNUMBER(AG8)),AF8+AG8,"n.a.")) -> 0.33333333 | AI8: =COUNTIF(D8:I8,"포수방해")+COUNTIF(V8:AA8,"포수방해") -> 0 | AJ8: =COUNTIF(D8:I8,"병살")+COUNTIF(V8:AA8,"병살") -> 0 | AK8: =COUNTIF(D8:I8,"실책출루")+COUNTIF(V8:AA8,"실책출루") -> 0 | AL8: =COUNTIF(D8:I8,"야수선택")+COUNTIF(V8:AA8,"야수선택") -> 0 | AM8: =COUNTIF(D8:I8,"안타")+COUNTIF(V8:AA8,"안타") -> 0 | AN8: =IF(AB8=0,"",R8/AB8) -> 0.33333333 | AO8: =IF(AB8=0,"",T8/AB8) -> 0.33333333
A9: 8 | B9: 아선수 | C9: 2B | D9: 땅볼 | E9: 2루타 | F9: 안타 | J9: 1 | K9: 0 | L9: 0 | M9: =AB9-R9-S9-AC9-AD9-AI9 -> 3 | N9: =SUM(O9:Q9)+AM9 -> 2 | O9: =COUNTIF(D9:I9,"2루타")+COUNTIF(V9:AA9,"2루타") -> 1 | P9: =COUNTIF(D9:I9,"3루타")+COUNTIF(V9:AA9,"3루타") -> 0 | Q9: =COUNTIF(D9:I9,"홈런")+COUNTIF(V9:AA9,"홈런") -> 0 | R9: =COUNTIF(D9:I9,"볼넷")+COUNTIF(V9:AA9,"볼넷") -> 0 | S9: =COUNTIF(D9:I9,"사구")+COUNTIF(V9:AA9,"사구") -> 0 | T9: =COUNTIF(D9:I9,"삼진")+COUNTIF(V9:AA9,"삼진")+COUNTIF(D9:I9,"루킹삼진")+COUNTIF(V9:AA9,"루킹삼진")+COUNTIF(D9:I9,"낫아웃출루")+COUNTIF(V9:AA9,"낫아웃출루") -> 0 | U9: =IF(AB9=0,"",IF(M9=0,"n.a.",N9/M9)) -> 0.66666667 | AB9: =COUNTA(D9:I9)+COUNTA(V9:AA9) -> 3 | AC9: =COUNTIF(D9:I9,"희생플라이")+COUNTIF(V9:AA9,"희생플라이") -> 0 | AD9: =COUNTIF(D9:I9,"희생번트")+COUNTIF(V9:AA9,"희생번트") -> 0 | AE9: =AM9+2*O9+3*P9+4*Q9 -> 3 | AF9: =IF(AB9=0,"",IF(M9+R9+S9+AC9=0,"n.a.",(N9+R9+S9)/(M9+R9+S9+AC9))) -> 0.66666667 | AG9: =IF(AB9=0,"",IF(M9=0,"n.a.",AE9/M9)) -> 1 | AH9: =IF(AB9=0,"",IF(AND(ISNUMBER(AF9),ISNUMBER(AG9)),AF9+AG9,"n.a.")) -> 1.6666667 | AI9: =COUNTIF(D9:I9,"포수방해")+COUNTIF(V9:AA9,"포수방해") -> 0 | AJ9: =COUNTIF(D9:I9,"병살")+COUNTIF(V9:AA9,"병살") -> 0 | AK9: =COUNTIF(D9:I9,"실책출루")+COUNTIF(V9:AA9,"실책출루") -> 0 | AL9: =COUNTIF(D9:I9,"야수선택")+COUNTIF(V9:AA9,"야수선택") -> 0 | AM9: =COUNTIF(D9:I9,"안타")+COUNTIF(V9:AA9,"안타") -> 1 | AN9: =IF(AB9=0,"",R9/AB9) -> 0 | AO9: =IF(AB9=0,"",T9/AB9) -> 0
A10: 9 | B10: 자선수 | C10: DH | D10: 삼진 | E10: 뜬공 | J10: 0 | K10: 0 | L10: 0 | M10: =AB10-R10-S10-AC10-AD10-AI10 -> 2 | N10: =SUM(O10:Q10)+AM10 -> 0 | O10: =COUNTIF(D10:I10,"2루타")+COUNTIF(V10:AA10,"2루타") -> 0 | P10: =COUNTIF(D10:I10,"3루타")+COUNTIF(V10:AA10,"3루타") -> 0 | Q10: =COUNTIF(D10:I10,"홈런")+COUNTIF(V10:AA10,"홈런") -> 0 | R10: =COUNTIF(D10:I10,"볼넷")+COUNTIF(V10:AA10,"볼넷") -> 0 | S10: =COUNTIF(D10:I10,"사구")+COUNTIF(V10:AA10,"사구") -> 0 | T10: =COUNTIF(D10:I10,"삼진")+COUNTIF(V10:AA10,"삼진")+COUNTIF(D10:I10,"루킹삼진")+COUNTIF(V10:AA10,"루킹삼진")+COUNTIF(D10:I10,"낫아웃출루")+COUNTIF(V10:AA10,"낫아웃출루") -> 1 | U10: =IF(AB10=0,"",IF(M10=0,"n.a.",N10/M10)) -> 0 | AB10: =COUNTA(D10:I10)+COUNTA(V10:AA10) -> 2 | AC10: =COUNTIF(D10:I10,"희생플라이")+COUNTIF(V10:AA10,"희생플라이") -> 0 | AD10: =COUNTIF(D10:I10,"희생번트")+COUNTIF(V10:AA10,"희생번트") -> 0 | AE10: =AM10+2*O10+3*P10+4*Q10 -> 0 | AF10: =IF(AB10=0,"",IF(M10+R10+S10+AC10=0,"n.a.",(N10+R10+S10)/(M10+R10+S10+AC10))) -> 0 | AG10: =IF(AB10=0,"",IF(M10=0,"n.a.",AE10/M10)) -> 0 | AH10: =IF(AB10=0,"",IF(AND(ISNUMBER(AF10),ISNUMBER(AG10)),AF10+AG10,"n.a.")) -> 0 | AI10: =COUNTIF(D10:I10,"포수방해")+COUNTIF(V10:AA10,"포수방해") -> 0 | AJ10: =COUNTIF(D10:I10,"병살")+COUNTIF(V10:AA10,"병살") -> 0 | AK10: =COUNTIF(D10:I10,"실책출루")+COUNTIF(V10:AA10,"실책출루") -> 0 | AL10: =COUNTIF(D10:I10,"야수선택")+COUNTIF(V10:AA10,"야수선택") -> 0 | AM10: =COUNTIF(D10:I10,"안타")+COUNTIF(V10:AA10,"안타") -> 0 | AN10: =IF(AB10=0,"",R10/AB10) -> 0 | AO10: =IF(AB10=0,"",T10/AB10) -> 0.5
M11: =AB11-R11-S11-AC11-AD11-AI11 -> 0 | N11: =SUM(O11:Q11)+AM11 -> 0 | O11: =COUNTIF(D11:I11,"2루타")+COUNTIF(V11:AA11,"2루타") -> 0 | P11: =COUNTIF(D11:I11,"3루타")+COUNTIF(V11:AA11,"3루타") -> 0 | Q11: =COUNTIF(D11:I11,"홈런")+COUNTIF(V11:AA11,"홈런") -> 0 | R11: =COUNTIF(D11:I11,"볼넷")+COUNTIF(V11:AA11,"볼넷") -> 0 | S11: =COUNTIF(D11:I11,"사구")+COUNTIF(V11:AA11,"사구") -> 0 | T11: =COUNTIF(D11:I11,"삼진")+COUNTIF(V11:AA11,"삼진")+COUNTIF(D11:I11,"루킹삼진")+COUNTIF(V11:AA11,"루킹삼진")+COUNTIF(D11:I11,"낫아웃출루")+COUNTIF(V11:AA11,"낫아웃출루") -> 0 | U11: =IF(AB11=0,"",IF(M11=0,"n.a.",N11/M11)) | AB11: =COUNTA(D11:I11)+COUNTA(V11:AA11) -> 0 | AC11: =COUNTIF(D11:I11,"희생플라이")+COUNTIF(V11:AA11,"희생플라이") -> 0 | AD11: =COUNTIF(D11:I11,"희생번트")+COUNTIF(V11:AA11,"희생번트") -> 0 | AE11: =AM11+2*O11+3*P11+4*Q11 -> 0 | AF11: =IF(AB11=0,"",IF(M11+R11+S11+AC11=0,"n.a.",(N11+R11+S11)/(M11+R11+S11+AC11))) | AG11: =IF(AB11=0,"",IF(M11=0,"n.a.",AE11/M11)) | AH11: =IF(AB11=0,"",IF(AND(ISNUMBER(AF11),ISNUMBER(AG11)),AF11+AG11,"n.a.")) | AI11: =COUNTIF(D11:I11,"포수방해")+COUNTIF(V11:AA11,"포수방해") -> 0 | AJ11: =COUNTIF(D11:I11,"병살")+COUNTIF(V11:AA11,"병살") -> 0 | AK11: =COUNTIF(D11:I11,"실책출루")+COUNTIF(V11:AA11,"실책출루") -> 0 | AL11: =COUNTIF(D11:I11,"야수선택")+COUNTIF(V11:AA11,"야수선택") -> 0 | AM11: =COUNTIF(D11:I11,"안타")+COUNTIF(V11:AA11,"안타") -> 0 | AN11: =IF(AB11=0,"",R11/AB11) | AO11: =IF(AB11=0,"",T11/AB11)
A12: 9 | B12: 차선수 | C12: PH | D12: 안타 | J12: 0 | K12: 0 | L12: 0 | M12: =AB12-R12-S12-AC12-AD12-AI12 -> 1 | N12: =SUM(O12:Q12)+AM12 -> 1 | O12: =COUNTIF(D12:I12,"2루타")+COUNTIF(V12:AA12,"2루타") -> 0 | P12: =COUNTIF(D12:I12,"3루타")+COUNTIF(V12:AA12,"3루타") -> 0 | Q12: =COUNTIF(D12:I12,"홈런")+COUNTIF(V12:AA12,"홈런") -> 0 | R12: =COUNTIF(D12:I12,"볼넷")+COUNTIF(V12:AA12,"볼넷") -> 0 | S12: =COUNTIF(D12:I12,"사구")+COUNTIF(V12:AA12,"사구") -> 0 | T12: =COUNTIF(D12:I12,"삼진")+COUNTIF(V12:AA12,"삼진")+COUNTIF(D12:I12,"루킹삼진")+COUNTIF(V12:AA12,"루킹삼진")+COUNTIF(D12:I12,"낫아웃출루")+COUNTIF(V12:AA12,"낫아웃출루") -> 0 | U12: =IF(AB12=0,"",IF(M12=0,"n.a.",N12/M12)) -> 1 | AB12: =COUNTA(D12:I12)+COUNTA(V12:AA12) -> 1 | AC12: =COUNTIF(D12:I12,"희생플라이")+COUNTIF(V12:AA12,"희생플라이") -> 0 | AD12: =COUNTIF(D12:I12,"희생번트")+COUNTIF(V12:AA12,"희생번트") -> 0 | AE12: =AM12+2*O12+3*P12+4*Q12 -> 1 | AF12: =IF(AB12=0,"",IF(M12+R12+S12+AC12=0,"n.a.",(N12+R12+S12)/(M12+R12+S12+AC12))) -> 1 | AG12: =IF(AB12=0,"",IF(M12=0,"n.a.",AE12/M12)) -> 1 | AH12: =IF(AB12=0,"",IF(AND(ISNUMBER(AF12),ISNUMBER(AG12)),AF12+AG12,"n.a.")) -> 2 | AI12: =COUNTIF(D12:I12,"포수방해")+COUNTIF(V12:AA12,"포수방해") -> 0 | AJ12: =COUNTIF(D12:I12,"병살")+COUNTIF(V12:AA12,"병살") -> 0 | AK12: =COUNTIF(D12:I12,"실책출루")+COUNTIF(V12:AA12,"실책출루") -> 0 | AL12: =COUNTIF(D12:I12,"야수선택")+COUNTIF(V12:AA12,"야수선택") -> 0 | AM12: =COUNTIF(D12:I12,"안타")+COUNTIF(V12:AA12,"안타") -> 1 | AN12: =IF(AB12=0,"",R12/AB12) -> 0 | AO12: =IF(AB12=0,"",T12/AB12) -> 0
M13: =AB13-R13-S13-AC13-AD13-AI13 -> 0 | N13: =SUM(O13:Q13)+AM13 -> 0 | O13: =COUNTIF(D13:I13,"2루타")+COUNTIF(V13:AA13,"2루타") -> 0 | P13: =COUNTIF(D13:I13,"3루타")+COUNTIF(V13:AA13,"3루타") -> 0 | Q13: =COUNTIF(D13:I13,"홈런")+COUNTIF(V13:AA13,"홈런") -> 0 | R13: =COUNTIF(D13:I13,"볼넷")+COUNTIF(V13:AA13,"볼넷") -> 0 | S13: =COUNTIF(D13:I13,"사구")+COUNTIF(V13:AA13,"사구") -> 0 | T13: =COUNTIF(D13:I13,"삼진")+COUNTIF(V13:AA13,"삼진")+COUNTIF(D13:I13,"루킹삼진")+COUNTIF(V13:AA13,"루킹삼진")+COUNTIF(D13:I13,"낫아웃출루")+COUNTIF(V13:AA13,"낫아웃출루") -> 0 | U13: =IF(AB13=0,"",IF(M13=0,"n.a.",N13/M13)) | AB13: =COUNTA(D13:I13)+COUNTA(V13:AA13) -> 0 | AC13: =COUNTIF(D13:I13,"희생플라이")+COUNTIF(V13:AA13,"희생플라이") -> 0 | AD13: =COUNTIF(D13:I13,"희생번트")+COUNTIF(V13:AA13,"희생번트") -> 0 | AE13: =AM13+2*O13+3*P13+4*Q13 -> 0 | AF13: =IF(AB13=0,"",IF(M13+R13+S13+AC13=0,"n.a.",(N13+R13+S13)/(M13+R13+S13+AC13))) | AG13: =IF(AB13=0,"",IF(M13=0,"n.a.",AE13/M13)) | AH13: =IF(AB13=0,"",IF(AND(ISNUMBER(AF13),ISNUMBER(AG13)),AF13+AG13,"n.a.")) | AI13: =COUNTIF(D13:I13,"포수방해")+COUNTIF(V13:AA13,"포수방해") -> 0 | AJ13: =COUNTIF(D13:I13,"병살")+COUNTIF(V13:AA13,"병살") -> 0 | AK13: =COUNTIF(D13:I13,"실책출루")+COUNTIF(V13:AA13,"실책출루") -> 0 | AL13: =COUNTIF(D13:I13,"야수선택")+COUNTIF(V13:AA13,"야수선택") -> 0 | AM13: =COUNTIF(D13:I13,"안타")+COUNTIF(V13:AA13,"안타") -> 0 | AN13: =IF(AB13=0,"",R13/AB13) | AO13: =IF(AB13=0,"",T13/AB13)
M14: =AB14-R14-S14-AC14-AD14-AI14 -> 0 | N14: =SUM(O14:Q14)+AM14 -> 0 | O14: =COUNTIF(D14:I14,"2루타")+COUNTIF(V14:AA14,"2루타") -> 0 | P14: =COUNTIF(D14:I14,"3루타")+COUNTIF(V14:AA14,"3루타") -> 0 | Q14: =COUNTIF(D14:I14,"홈런")+COUNTIF(V14:AA14,"홈런") -> 0 | R14: =COUNTIF(D14:I14,"볼넷")+COUNTIF(V14:AA14,"볼넷") -> 0 | S14: =COUNTIF(D14:I14,"사구")+COUNTIF(V14:AA14,"사구") -> 0 | T14: =COUNTIF(D14:I14,"삼진")+COUNTIF(V14:AA14,"삼진")+COUNTIF(D14:I14,"루킹삼진")+COUNTIF(V14:AA14,"루킹삼진")+COUNTIF(D14:I14,"낫아웃출루")+COUNTIF(V14:AA14,"낫아웃출루") -> 0 | U14: =IF(AB14=0,"",IF(M14=0,"n.a.",N14/M14)) | AB14: =COUNTA(D14:I14)+COUNTA(V14:AA14) -> 0 | AC14: =COUNTIF(D14:I14,"희생플라이")+COUNTIF(V14:AA14,"희생플라이") -> 0 | AD14: =COUNTIF(D14:I14,"희생번트")+COUNTIF(V14:AA14,"희생번트") -> 0 | AE14: =AM14+2*O14+3*P14+4*Q14 -> 0 | AF14: =IF(AB14=0,"",IF(M14+R14+S14+AC14=0,"n.a.",(N14+R14+S14)/(M14+R14+S14+AC14))) | AG14: =IF(AB14=0,"",IF(M14=0,"n.a.",AE14/M14)) | AH14: =IF(AB14=0,"",IF(AND(ISNUMBER(AF14),ISNUMBER(AG14)),AF14+AG14,"n.a.")) | AI14: =COUNTIF(D14:I14,"포수방해")+COUNTIF(V14:AA14,"포수방해") -> 0 | AJ14: =COUNTIF(D14:I14,"병살")+COUNTIF(V14:AA14,"병살") -> 0 | AK14: =COUNTIF(D14:I14,"실책출루")+COUNTIF(V14:AA14,"실책출루") -> 0 | AL14: =COUNTIF(D14:I14,"야수선택")+COUNTIF(V14:AA14,"야수선택") -> 0 | AM14: =COUNTIF(D14:I14,"안타")+COUNTIF(V14:AA14,"안타") -> 0 | AN14: =IF(AB14=0,"",R14/AB14) | AO14: =IF(AB14=0,"",T14/AB14)
M15: =AB15-R15-S15-AC15-AD15-AI15 -> 0 | N15: =SUM(O15:Q15)+AM15 -> 0 | O15: =COUNTIF(D15:I15,"2루타")+COUNTIF(V15:AA15,"2루타") -> 0 | P15: =COUNTIF(D15:I15,"3루타")+COUNTIF(V15:AA15,"3루타") -> 0 | Q15: =COUNTIF(D15:I15,"홈런")+COUNTIF(V15:AA15,"홈런") -> 0 | R15: =COUNTIF(D15:I15,"볼넷")+COUNTIF(V15:AA15,"볼넷") -> 0 | S15: =COUNTIF(D15:I15,"사구")+COUNTIF(V15:AA15,"사구") -> 0 | T15: =COUNTIF(D15:I15,"삼진")+COUNTIF(V15:AA15,"삼진")+COUNTIF(D15:I15,"루킹삼진")+COUNTIF(V15:AA15,"루킹삼진")+COUNTIF(D15:I15,"낫아웃출루")+COUNTIF(V15:AA15,"낫아웃출루") -> 0 | U15: =IF(AB15=0,"",IF(M15=0,"n.a.",N15/M15)) | AB15: =COUNTA(D15:I15)+COUNTA(V15:AA15) -> 0 | AC15: =COUNTIF(D15:I15,"희생플라이")+COUNTIF(V15:AA15,"희생플라이") -> 0 | AD15: =COUNTIF(D15:I15,"희생번트")+COUNTIF(V15:AA15,"희생번트") -> 0 | AE15: =AM15+2*O15+3*P15+4*Q15 -> 0 | AF15: =IF(AB15=0,"",IF(M15+R15+S15+AC15=0,"n.a.",(N15+R15+S15)/(M15+R15+S15+AC15))) | AG15: =IF(AB15=0,"",IF(M15=0,"n.a.",AE15/M15)) | AH15: =IF(AB15=0,"",IF(AND(ISNUMBER(AF15),ISNUMBER(AG15)),AF15+AG15,"n.a.")) | AI15: =COUNTIF(D15:I15,"포수방해")+COUNTIF(V15:AA15,"포수방해") -> 0 | AJ15: =COUNTIF(D15:I15,"병살")+COUNTIF(V15:AA15,"병살") -> 0 | AK15: =COUNTIF(D15:I15,"실책출루")+COUNTIF(V15:AA15,"실책출루") -> 0 | AL15: =COUNTIF(D15:I15,"야수선택")+COUNTIF(V15:AA15,"야수선택") -> 0 | AM15: =COUNTIF(D15:I15,"안타")+COUNTIF(V15:AA15,"안타") -> 0 | AN15: =IF(AB15=0,"",R15/AB15) | AO15: =IF(AB15=0,"",T15/AB15)
M16: =AB16-R16-S16-AC16-AD16-AI16 -> 0 | N16: =SUM(O16:Q16)+AM16 -> 0 | O16: =COUNTIF(D16:I16,"2루타")+COUNTIF(V16:AA16,"2루타") -> 0 | P16: =COUNTIF(D16:I16,"3루타")+COUNTIF(V16:AA16,"3루타") -> 0 | Q16: =COUNTIF(D16:I16,"홈런")+COUNTIF(V16:AA16,"홈런") -> 0 | R16: =COUNTIF(D16:I16,"볼넷")+COUNTIF(V16:AA16,"볼넷") -> 0 | S16: =COUNTIF(D16:I16,"사구")+COUNTIF(V16:AA16,"사구") -> 0 | T16: =COUNTIF(D16:I16,"삼진")+COUNTIF(V16:AA16,"삼진")+COUNTIF(D16:I16,"루킹삼진")+COUNTIF(V16:AA16,"루킹삼진")+COUNTIF(D16:I16,"낫아웃출루")+COUNTIF(V16:AA16,"낫아웃출루") -> 0 | U16: =IF(AB16=0,"",IF(M16=0,"n.a.",N16/M16)) | AB16: =COUNTA(D16:I16)+COUNTA(V16:AA16) -> 0 | AC16: =COUNTIF(D16:I16,"희생플라이")+COUNTIF(V16:AA16,"희생플라이") -> 0 | AD16: =COUNTIF(D16:I16,"희생번트")+COUNTIF(V16:AA16,"희생번트") -> 0 | AE16: =AM16+2*O16+3*P16+4*Q16 -> 0 | AF16: =IF(AB16=0,"",IF(M16+R16+S16+AC16=0,"n.a.",(N16+R16+S16)/(M16+R16+S16+AC16))) | AG16: =IF(AB16=0,"",IF(M16=0,"n.a.",AE16/M16)) | AH16: =IF(AB16=0,"",IF(AND(ISNUMBER(AF16),ISNUMBER(AG16)),AF16+AG16,"n.a.")) | AI16: =COUNTIF(D16:I16,"포수방해")+COUNTIF(V16:AA16,"포수방해") -> 0 | AJ16: =COUNTIF(D16:I16,"병살")+COUNTIF(V16:AA16,"병살") -> 0 | AK16: =COUNTIF(D16:I16,"실책출루")+COUNTIF(V16:AA16,"실책출루") -> 0 | AL16: =COUNTIF(D16:I16,"야수선택")+COUNTIF(V16:AA16,"야수선택") -> 0 | AM16: =COUNTIF(D16:I16,"안타")+COUNTIF(V16:AA16,"안타") -> 0 | AN16: =IF(AB16=0,"",R16/AB16) | AO16: =IF(AB16=0,"",T16/AB16)
B17: 합계 | J17: =SUM(J2:J16) -> 4 | K17: =SUM(K2:K16) -> 4 | L17: =SUM(L2:L16) -> 2 | M17: =SUM(M2:M16) -> 25 | N17: =SUM(N2:N16) -> 10 | O17: =SUM(O2:O16) -> 2 | P17: =SUM(P2:P16) -> 1 | Q17: =SUM(Q2:Q16) -> 1 | ... T17: =SUM(T2:T16) -> 5 | U17: =IF(AB17=0,"",IF(M17=0,"n.a.",N17/M17)) -> 0.4 | AB17: =SUM(AB2:AB16) -> 32 | AC17: =SUM(AC2:AC16) -> 1 | AD17: =SUM(AD2:AD16) -> 1 | AE17: =SUM(AE2:AE16) -> 17 | AF17: =IF(AB17=0,"",IF(M17+R17+S17+AC17=0,"n.a.",(N17+R17+S17)/(M17+R17+S17+AC17))) -> 0.46666667 | AG17: =IF(AB17=0,"",IF(M17=0,"n.a.",AE17/M17)) -> 0.68 | AH17: =IF(AB17=0,"",IF(AND(ISNUMBER(AF17),ISNUMBER(AG17)),AF17+AG17,"n.a.")) -> 1.1466667 | AI17: =SUM(AI2:AI16) -> 1 | AJ17: =SUM(AJ2:AJ16) -> 1 | AK17: =SUM(AK2:AK16) -> 1 | AL17: =SUM(AL2:AL16) -> 1 | AM17: =SUM(AM2:AM16) -> 6 | AN17: =IF(AB17=0,"",IF(AB17=0,"n.a.",R17/AB17)) -> 0.09375 | AO17: =IF(AB17=0,"",IF(AB17=0,"n.a.",T17/AB17)) -> 0.15625
A19: 추가 타석은 V:AA(7–12타석)에 입력. 교체 선수는 11–16행에 별도 기록하고 타순은 원래 타순 사용.
A20: 낫아웃출루는 삼진·타수에 포함. 포수방해는 타석에 포함하고 타수·OBP 분모에서 제외. 병살은 땅볼 병살타.
A21: 타율·비율은 반올림하지 않은 값으로 계산하고 화면에서만 반올림. 팀 비율은 합계 분자/합계 분모로 계산.

Sheet 투수 기록
A1: 이름 | B1: 결과 | C1: 아웃 | D1: 이닝 | E1: 투구수 | F1: 피안타 | G1: 실점 | H1: 자책 | I1: 볼넷 | J1: 사구 | K1: 삼진 | L1: 피홈런 | M1: ERA | N1: WHIP | O1: K/BB | P1: K/9 | Q1: BB/9 | R1: 이닝 표기 | S1: 입력 상태
A2: 카선수 | B2: 승 | C2: 12 | D2: =IF(A2="","",IF(NOT(ISNUMBER(C2)),"",C2/3)) -> 4 | E2: 60 | F2: 3 | G2: 2 | H2: 1 | I2: 2 | J2: 1 | K2: 5 | L2: 1 | M2: =IF(A2="","",IF(OR(NOT(ISNUMBER(C2)),NOT(ISNUMBER(H2))),"",IF(C2=0,"n.a.",H2*3*'경기 정보'!$C$20/C2))) -> 1.25 | N2: =IF(A2="","",IF(OR(NOT(ISNUMBER(C2)),NOT(ISNUMBER(F2)),NOT(ISNUMBER(I2))),"",IF(C2=0,"n.a.",(F2+I2)*3/C2))) -> 1.25 | O2: =IF(A2="","",IF(OR(NOT(ISNUMBER(I2)),NOT(ISNUMBER(K2))),"",IF(I2=0,"n.a.",K2/I2))) -> 2.5 | P2: =IF(A2="","",IF(OR(NOT(ISNUMBER(C2)),NOT(ISNUMBER(K2))),"",IF(C2=0,"n.a.",K2*27/C2))) -> 11.25 | Q2: =IF(A2="","",IF(OR(NOT(ISNUMBER(C2)),NOT(ISNUMBER(I2))),"",IF(C2=0,"n.a.",I2*27/C2))) -> 4.5 | R2: =IF(A2="","",IF(NOT(ISNUMBER(C2)),"",INT(C2/3)&"."&MOD(C2,3))) -> 4.0 | S2: =IF(A2="","",IF(COUNT(C2,E2:L2)=9,"입력 완료","숫자 입력 대기")) -> 입력 완료
A3: 타선수 | B3: 홀 | C3: 6 | D3: =IF(A3="","",IF(NOT(ISNUMBER(C3)),"",C3/3)) -> 2 | E3: 25 | F3: 1 | G3: 0 | H3: 0 | I3: 1 | J3: 0 | K3: 3 | L3: 0 | M3: =IF(A3="","",IF(OR(NOT(ISNUMBER(C3)),NOT(ISNUMBER(H3))),"",IF(C3=0,"n.a.",H3*3*'경기 정보'!$C$20/C3))) -> 0 | N3: =IF(A3="","",IF(OR(NOT(ISNUMBER(C3)),NOT(ISNUMBER(F3)),NOT(ISNUMBER(I3))),"",IF(C3=0,"n.a.",(F3+I3)*3/C3))) -> 1 | O3: =IF(A3="","",IF(OR(NOT(ISNUMBER(I3)),NOT(ISNUMBER(K3))),"",IF(I3=0,"n.a.",K3/I3))) -> 3 | P3: =IF(A3="","",IF(OR(NOT(ISNUMBER(C3)),NOT(ISNUMBER(K3))),"",IF(C3=0,"n.a.",K3*27/C3))) -> 13.5 | Q3: =IF(A3="","",IF(OR(NOT(ISNUMBER(C3)),NOT(ISNUMBER(I3))),"",IF(C3=0,"n.a.",I3*27/C3))) -> 4.5 | R3: =IF(A3="","",IF(NOT(ISNUMBER(C3)),"",INT(C3/3)&"."&MOD(C3,3))) -> 2.0 | S3: =IF(A3="","",IF(COUNT(C3,E3:L3)=9,"입력 완료","숫자 입력 대기")) -> 입력 완료
A4: 파선수 | B4: 세 | C4: 3 | D4: =IF(A4="","",IF(NOT(ISNUMBER(C4)),"",C4/3)) -> 1 | E4: 12 | F4: 0 | G4: 0 | H4: 0 | I4: 0 | J4: 0 | K4: 2 | L4: 0 | M4: =IF(A4="","",IF(OR(NOT(ISNUMBER(C4)),NOT(ISNUMBER(H4))),"",IF(C4=0,"n.a.",H4*3*'경기 정보'!$C$20/C4))) -> 0 | N4: =IF(A4="","",IF(OR(NOT(ISNUMBER(C4)),NOT(ISNUMBER(F4)),NOT(ISNUMBER(I4))),"",IF(C4=0,"n.a.",(F4+I4)*3/C4))) -> 0 | O4: =IF(A4="","",IF(OR(NOT(ISNUMBER(I4)),NOT(ISNUMBER(K4))),"",IF(I4=0,"n.a.",K4/I4))) -> n.a. | P4: =IF(A4="","",IF(OR(NOT(ISNUMBER(C4)),NOT(ISNUMBER(K4))),"",IF(C4=0,"n.a.",K4*27/C4))) -> 18 | Q4: =IF(A4="","",IF(OR(NOT(ISNUMBER(C4)),NOT(ISNUMBER(I4))),"",IF(C4=0,"n.a.",I4*27/C4))) -> 0 | R4: =IF(A4="","",IF(NOT(ISNUMBER(C4)),"",INT(C4/3)&"."&MOD(C4,3))) -> 1.0 | S4: =IF(A4="","",IF(COUNT(C4,E4:L4)=9,"입력 완료","숫자 입력 대기")) -> 입력 완료
D5: =IF(A5="","",IF(NOT(ISNUMBER(C5)),"",C5/3)) | M5: =IF(A5="","",IF(OR(NOT(ISNUMBER(C5)),NOT(ISNUMBER(H5))),"",IF(C5=0,"n.a.",H5*3*'경기 정보'!$C$20/C5))) | N5: =IF(A5="","",IF(OR(NOT(ISNUMBER(C5)),NOT(ISNUMBER(F5)),NOT(ISNUMBER(I5))),"",IF(C5=0,"n.a.",(F5+I5)*3/C5))) | O5: =IF(A5="","",IF(OR(NOT(ISNUMBER(I5)),NOT(ISNUMBER(K5))),"",IF(I5=0,"n.a.",K5/I5))) | P5: =IF(A5="","",IF(OR(NOT(ISNUMBER(C5)),NOT(ISNUMBER(K5))),"",IF(C5=0,"n.a.",K5*27/C5))) | Q5: =IF(A5="","",IF(OR(NOT(ISNUMBER(C5)),NOT(ISNUMBER(I5))),"",IF(C5=0,"n.a.",I5*27/C5))) | R5: =IF(A5="","",IF(NOT(ISNUMBER(C5)),"",INT(C5/3)&"."&MOD(C5,3))) | S5: =IF(A5="","",IF(COUNT(C5,E5:L5)=9,"입력 완료","숫자 입력 대기"))
D6: =IF(A6="","",IF(NOT(ISNUMBER(C6)),"",C6/3)) | M6: =IF(A6="","",IF(OR(NOT(ISNUMBER(C6)),NOT(ISNUMBER(H6))),"",IF(C6=0,"n.a.",H6*3*'경기 정보'!$C$20/C6))) | N6: =IF(A6="","",IF(OR(NOT(ISNUMBER(C6)),NOT(ISNUMBER(F6)),NOT(ISNUMBER(I6))),"",IF(C6=0,"n.a.",(F6+I6)*3/C6))) | O6: =IF(A6="","",IF(OR(NOT(ISNUMBER(I6)),NOT(ISNUMBER(K6))),"",IF(I6=0,"n.a.",K6/I6))) | P6: =IF(A6="","",IF(OR(NOT(ISNUMBER(C6)),NOT(ISNUMBER(K6))),"",IF(C6=0,"n.a.",K6*27/C6))) | Q6: =IF(A6="","",IF(OR(NOT(ISNUMBER(C6)),NOT(ISNUMBER(I6))),"",IF(C6=0,"n.a.",I6*27/C6))) | R6: =IF(A6="","",IF(NOT(ISNUMBER(C6)),"",INT(C6/3)&"."&MOD(C6,3))) | S6: =IF(A6="","",IF(COUNT(C6,E6:L6)=9,"입력 완료","숫자 입력 대기"))
D7: =IF(A7="","",IF(NOT(ISNUMBER(C7)),"",C7/3)) | M7: =IF(A7="","",IF(OR(NOT(ISNUMBER(C7)),NOT(ISNUMBER(H7))),"",IF(C7=0,"n.a.",H7*3*'경기 정보'!$C$20/C7))) | N7: =IF(A7="","",IF(OR(NOT(ISNUMBER(C7)),NOT(ISNUMBER(F7)),NOT(ISNUMBER(I7))),"",IF(C7=0,"n.a.",(F7+I7)*3/C7))) | O7: =IF(A7="","",IF(OR(NOT(ISNUMBER(I7)),NOT(ISNUMBER(K7))),"",IF(I7=0,"n.a.",K7/I7))) | P7: =IF(A7="","",IF(OR(NOT(ISNUMBER(C7)),NOT(ISNUMBER(K7))),"",IF(C7=0,"n.a.",K7*27/C7))) | Q7: =IF(A7="","",IF(OR(NOT(ISNUMBER(C7)),NOT(ISNUMBER(I7))),"",IF(C7=0,"n.a.",I7*27/C7))) | R7: =IF(A7="","",IF(NOT(ISNUMBER(C7)),"",INT(C7/3)&"."&MOD(C7,3))) | S7: =IF(A7="","",IF(COUNT(C7,E7:L7)=9,"입력 완료","숫자 입력 대기"))
D8: =IF(A8="","",IF(NOT(ISNUMBER(C8)),"",C8/3)) | M8: =IF(A8="","",IF(OR(NOT(ISNUMBER(C8)),NOT(ISNUMBER(H8))),"",IF(C8=0,"n.a.",H8*3*'경기 정보'!$C$20/C8))) | N8: =IF(A8="","",IF(OR(NOT(ISNUMBER(C8)),NOT(ISNUMBER(F8)),NOT(ISNUMBER(I8))),"",IF(C8=0,"n.a.",(F8+I8)*3/C8))) | O8: =IF(A8="","",IF(OR(NOT(ISNUMBER(I8)),NOT(ISNUMBER(K8))),"",IF(I8=0,"n.a.",K8/I8))) | P8: =IF(A8="","",IF(OR(NOT(ISNUMBER(C8)),NOT(ISNUMBER(K8))),"",IF(C8=0,"n.a.",K8*27/C8))) | Q8: =IF(A8="","",IF(OR(NOT(ISNUMBER(C8)),NOT(ISNUMBER(I8))),"",IF(C8=0,"n.a.",I8*27/C8))) | R8: =IF(A8="","",IF(NOT(ISNUMBER(C8)),"",INT(C8/3)&"."&MOD(C8,3))) | S8: =IF(A8="","",IF(COUNT(C8,E8:L8)=9,"입력 완료","숫자 입력 대기"))
D9: =IF(A9="","",IF(NOT(ISNUMBER(C9)),"",C9/3)) | M9: =IF(A9="","",IF(OR(NOT(ISNUMBER(C9)),NOT(ISNUMBER(H9))),"",IF(C9=0,"n.a.",H9*3*'경기 정보'!$C$20/C9))) | N9: =IF(A9="","",IF(OR(NOT(ISNUMBER(C9)),NOT(ISNUMBER(F9)),NOT(ISNUMBER(I9))),"",IF(C9=0,"n.a.",(F9+I9)*3/C9))) | O9: =IF(A9="","",IF(OR(NOT(ISNUMBER(I9)),NOT(ISNUMBER(K9))),"",IF(I9=0,"n.a.",K9/I9))) | P9: =IF(A9="","",IF(OR(NOT(ISNUMBER(C9)),NOT(ISNUMBER(K9))),"",IF(C9=0,"n.a.",K9*27/C9))) | Q9: =IF(A9="","",IF(OR(NOT(ISNUMBER(C9)),NOT(ISNUMBER(I9))),"",IF(C9=0,"n.a.",I9*27/C9))) | R9: =IF(A9="","",IF(NOT(ISNUMBER(C9)),"",INT(C9/3)&"."&MOD(C9,3))) | S9: =IF(A9="","",IF(COUNT(C9,E9:L9)=9,"입력 완료","숫자 입력 대기"))
D10: =IF(A10="","",IF(NOT(ISNUMBER(C10)),"",C10/3)) | M10: =IF(A10="","",IF(OR(NOT(ISNUMBER(C10)),NOT(ISNUMBER(H10))),"",IF(C10=0,"n.a.",H10*3*'경기 정보'!$C$20/C10))) | N10: =IF(A10="","",IF(OR(NOT(ISNUMBER(C10)),NOT(ISNUMBER(F10)),NOT(ISNUMBER(I10))),"",IF(C10=0,"n.a.",(F10+I10)*3/C10))) | O10: =IF(A10="","",IF(OR(NOT(ISNUMBER(I10)),NOT(ISNUMBER(K10))),"",IF(I10=0,"n.a.",K10/I10))) | P10: =IF(A10="","",IF(OR(NOT(ISNUMBER(C10)),NOT(ISNUMBER(K10))),"",IF(C10=0,"n.a.",K10*27/C10))) | Q10: =IF(A10="","",IF(OR(NOT(ISNUMBER(C10)),NOT(ISNUMBER(I10))),"",IF(C10=0,"n.a.",I10*27/C10))) | R10: =IF(A10="","",IF(NOT(ISNUMBER(C10)),"",INT(C10/3)&"."&MOD(C10,3))) | S10: =IF(A10="","",IF(COUNT(C10,E10:L10)=9,"입력 완료","숫자 입력 대기"))
D11: =IF(A11="","",IF(NOT(ISNUMBER(C11)),"",C11/3)) | M11: =IF(A11="","",IF(OR(NOT(ISNUMBER(C11)),NOT(ISNUMBER(H11))),"",IF(C11=0,"n.a.",H11*3*'경기 정보'!$C$20/C11))) | N11: =IF(A11="","",IF(OR(NOT(ISNUMBER(C11)),NOT(ISNUMBER(F11)),NOT(ISNUMBER(I11))),"",IF(C11=0,"n.a.",(F11+I11)*3/C11))) | O11: =IF(A11="","",IF(OR(NOT(ISNUMBER(I11)),NOT(ISNUMBER(K11))),"",IF(I11=0,"n.a.",K11/I11))) | P11: =IF(A11="","",IF(OR(NOT(ISNUMBER(C11)),NOT(ISNUMBER(K11))),"",IF(C11=0,"n.a.",K11*27/C11))) | Q11: =IF(A11="","",IF(OR(NOT(ISNUMBER(C11)),NOT(ISNUMBER(I11))),"",IF(C11=0,"n.a.",I11*27/C11))) | R11: =IF(A11="","",IF(NOT(ISNUMBER(C11)),"",INT(C11/3)&"."&MOD(C11,3))) | S11: =IF(A11="","",IF(COUNT(C11,E11:L11)=9,"입력 완료","숫자 입력 대기"))
A12: 합계 | C12: =SUM(C2:C11) -> 21 | D12: =IF(S12<>"입력 완료","",IF(COUNTA(A2:A11)=0,"",IF(NOT(ISNUMBER(C12)),"",C12/3))) -> 7 | E12: =SUM(E2:E11) -> 97 | F12: =SUM(F2:F11) -> 4 | G12: =SUM(G2:G11) -> 2 | H12: =SUM(H2:H11) -> 1 | I12: =SUM(I2:I11) -> 3 | J12: =SUM(J2:J11) -> 1 | K12: =SUM(K2:K11) -> 10 | L12: =SUM(L2:L11) -> 1 | M12: =IF(S12<>"입력 완료","",IF(COUNTA(A2:A11)=0,"",IF(OR(NOT(ISNUMBER(C12)),NOT(ISNUMBER(H12))),"",IF(C12=0,"n.a.",H12*3*'경기 정보'!$C$20/C12)))) -> 0.71428571 | N12: =IF(S12<>"입력 완료","",IF(COUNTA(A2:A11)=0,"",IF(OR(NOT(ISNUMBER(C12)),NOT(ISNUMBER(F12)),NOT(ISNUMBER(I12))),"",IF(C12=0,"n.a.",(F12+I12)*3/C12)))) -> 1 | O12: =IF(S12<>"입력 완료","",IF(COUNTA(A2:A11)=0,"",IF(OR(NOT(ISNUMBER(I12)),NOT(ISNUMBER(K12))),"",IF(I12=0,"n.a.",K12/I12)))) -> 3.3333333 | P12: =IF(S12<>"입력 완료","",IF(COUNTA(A2:A11)=0,"",IF(OR(NOT(ISNUMBER(C12)),NOT(ISNUMBER(K12))),"",IF(C12=0,"n.a.",K12*27/C12)))) -> 12.857143 | Q12: =IF(S12<>"입력 완료","",IF(COUNTA(A2:A11)=0,"",IF(OR(NOT(ISNUMBER(C12)),NOT(ISNUMBER(I12))),"",IF(C12=0,"n.a.",I12*27/C12)))) -> 3.8571429 | R12: =IF(S12<>"입력 완료","",IF(COUNTA(A2:A11)=0,"",IF(NOT(ISNUMBER(C12)),"",INT(C12/3)&"."&MOD(C12,3)))) -> 7.0 | S12: =IF(COUNTA(A2:A11)=0,"입력 대기",IF(COUNTIF(S2:S11,"숫자 입력 대기")>0,"숫자 입력 대기","입력 완료")) -> 입력 완료
A14: 아웃 수만 입력. D열은 실제 이닝(8/3), R열은 야구 표기(2.2). ERA·WHIP는 아웃 수로 계산.
A15: 자책점은 실책·포일이 없었던 이닝을 재구성해 판정. 미확정이면 빈칸으로 두고 주요 기록에 메모.
A16: 이름이 있는 투수는 C열과 E:L열 모두 입력(기록 없음은 0). 아웃 0개·볼넷 0개의 해당 비율은 n.a.

Sheet 주요 기록
A1: 결승타 | B1: 5회 1사 2루 가선수 2루타 | D1: B열에 이닝·아웃·선수·플레이 결과·판정 근거 입력.
A2: 2루타 | D2: 투수 교체 시 잔류 주자와 책임 투수, 자책점 미확정 장면은 필수 메모.
A3: 3루타
A4: 홈런
A5: 주루·도루
A6: 실책
A7: 주루사 | D7: 비어 있는 항목은 저장되지 않으니 억지로 채우지 않아도 됩니다.
A8: 견제사
A9: 병살타
A10: 폭투
A11: 투수 교체 판단
A12: 특이사항

Sheet 검수
B1: 기록 검수
B2: 숫자 대조와 플레이 판정은 별도로 확인. 빈 필수 입력은 통과로 처리하지 않음.
B4: 확인 항목 | C4: 기준값 | D4: 기록값 | E4: 차이 | F4: 상태 | G4: 확인 위치
B5: 우리 점수 대조 | C5: =IF(NOT(ISNUMBER('경기 정보'!C8)),"",'경기 정보'!C8) -> 4 | D5: =SUM('타자 기록'!J2:J16) -> 4 | E5: =IF(OR(NOT(ISNUMBER(C5)),NOT(ISNUMBER(D5))),"",D5-C5) -> 0 | F5: =IF(NOT(ISNUMBER(C5)),"입력 대기",IF(C5=D5,"통과","확인 필요")) -> 통과 | G5: 경기 정보 C8 / 타자 기록 J
B6: 상대 점수 대조 | C6: =IF(NOT(ISNUMBER('경기 정보'!C9)),"",'경기 정보'!C9) -> 2 | D6: =SUM('투수 기록'!G2:G11) -> 2 | E6: =IF(OR(NOT(ISNUMBER(C6)),NOT(ISNUMBER(D6))),"",D6-C6) -> 0 | F6: =IF(NOT(ISNUMBER(C6)),"입력 대기",IF(C6=D6,"통과","확인 필요")) -> 통과 | G6: 경기 정보 C9 / 투수 기록 G
B7: 수비 아웃 수 대조 | C7: =IF(NOT(ISNUMBER('경기 정보'!C21)),"",'경기 정보'!C21) -> 21 | D7: =SUM('투수 기록'!C2:C11) -> 21 | E7: =IF(OR(NOT(ISNUMBER(C7)),NOT(ISNUMBER(D7))),"",D7-C7) -> 0 | F7: =IF(NOT(ISNUMBER(C7)),"입력 대기",IF(C7=D7,"통과","확인 필요")) -> 통과 | G7: 경기 정보 C10 / 투수 기록 C
B8: 타점 합계 ≤ 득점 합계 | C8: =SUM('타자 기록'!J2:J16) -> 4 | D8: =SUM('타자 기록'!K2:K16) -> 4 | E8: =IF(OR(NOT(ISNUMBER(C8)),NOT(ISNUMBER(D8))),"",D8-C8) -> 0 | F8: =IF(NOT(ISNUMBER('경기 정보'!C8)),"입력 대기",IF(D8<=C8,"통과","확인 필요")) -> 통과 | G8: 타자 기록 J:K
B9: 타석 분해 일치 | C9: ='타자 기록'!AB17 -> 32 | D9: =SUM('타자 기록'!M17,'타자 기록'!R17,'타자 기록'!S17,'타자 기록'!AC17,'타자 기록'!AD17,'타자 기록'!AI17) -> 32 | E9: =IF(OR(NOT(ISNUMBER(C9)),NOT(ISNUMBER(D9))),"",D9-C9) -> 0 | F9: =IF(C9=0,"입력 대기",IF(C9=D9,"통과","확인 필요")) -> 통과 | G9: PA = AB + BB + HBP + SF + SH + CI
B10: 타자 명단 9명 이상 | C10: =9 -> 9 | D10: =COUNTA('타자 기록'!B2:B16) -> 10 | E10: =IF(OR(NOT(ISNUMBER(C10)),NOT(ISNUMBER(D10))),"",D10-C10) -> 1 | F10: =IF(D10>=C10,"통과","확인 필요") -> 통과 | G10: 교체 선수는 별도 행
B11: 투수 명단 1명 이상 | C11: =1 -> 1 | D11: =COUNTA('투수 기록'!A2:A11) -> 3 | E11: =IF(OR(NOT(ISNUMBER(C11)),NOT(ISNUMBER(D11))),"",D11-C11) -> 2 | F11: =IF(D11>=C11,"통과","확인 필요") -> 통과 | G11: 투수 기록 A
B12: 선발 타순 1–9 각 1회 | C12: =9 -> 9 | D12: =IF(COUNTIF('타자 기록'!A2:A10,1)=1,1,0)+IF(COUNTIF('타자 기록'!A2:A10,2)=1,1,0)+IF(COUNTIF('타자 기록'!A2:A10,3)=1,1,0)+IF(COUNTIF('타자 기록'!A2:A10,4)=1,1,0)+IF(COUNTIF('타자 기록'!A2:A10,5)=1,1,0)+IF(COUNTIF('타자 기록'!A2:A10,6)=1,1,0)+IF(COUNTIF('타자 기록'!A2:A10,7)=1,1,0)+IF(COUNTIF('타자 기록'!A2:A10,8)=1,1,0)+IF(COUNTIF('타자 기록'!A2:A10,9)=1,1,0) -> 9 | E12: =IF(OR(NOT(ISNUMBER(C12)),NOT(ISNUMBER(D12))),"",D12-C12) -> 0 | F12: =IF(C12=D12,"통과","확인 필요") -> 통과 | G12: 2–10행 선발. 교체 행의 같은 타순은 허용.
B13: 승·패 표기와 점수 일치 | C13: =1 -> 1 | D13: =IF(OR(NOT(ISNUMBER('경기 정보'!C8)),NOT(ISNUMBER('경기 정보'!C9))),"",IF('경기 정보'!C8>'경기 정보'!C9,IF(AND(COUNTIF('투수 기록'!B2:B11,"승")=1,COUNTIF('투수 기록'!B2:B11,"패")=0),1,0),IF('경기 정보'!C8<'경기 정보'!C9,IF(AND(COUNTIF('투수 기록'!B2:B11,"패")=1,COUNTIF('투수 기록'!B2:B11,"승")=0),1,0),IF(COUNTIF('투수 기록'!B2:B11,"승")+COUNTIF('투수 기록'!B2:B11,"패")=0,1,0)))) -> 1 | E13: =IF(OR(NOT(ISNUMBER(C13)),NOT(ISNUMBER(D13))),"",D13-C13) -> 0 | F13: =IF(NOT(ISNUMBER(D13)),"입력 대기",IF(C13=D13,"통과","확인 필요")) -> 통과 | G13: 무승부: 승·패 없음
B14: 경기 필수 정보 입력 | C14: =5 -> 5 | D14: =COUNTA('경기 정보'!C4:C5)+COUNTA('경기 정보'!C8:C10) -> 5 | E14: =IF(OR(NOT(ISNUMBER(C14)),NOT(ISNUMBER(D14))),"",D14-C14) -> 0 | F14: =IF(C14=D14,"통과","입력 대기") -> 통과 | G14: 날짜·상대팀·양 팀 점수·수비 이닝
B15: 목록 밖 타석 결과 없음 | C15: =0 -> 0 | D15: ='타자 기록'!AB17-(COUNTIF('타자 기록'!D2:I16,"안타")+COUNTIF('타자 기록'!V2:AA16,"안타")+COUNTIF('타자 기록'!D2:I16,"2루타")+COUNTIF('타자 기록'!V2:AA16,"2루타")+COUNTIF('타자 기록'!D2:I16,"3루타")+COUNTIF('타자 기록'!V2:AA16,"3루타")+COUNTIF('타자 기록'!D2:I16,"홈런")+COUNTIF('타자 기록'!V2:AA16,"홈런")+COUNTIF('타자 기록'!D2:I16,"삼진")+COUNTIF('타자 기록'!V2:AA16,"삼진")+COUNTIF('타자 기록'!D2:I16,"루킹삼진")+COUNTIF('타자 기록'!V2:AA16,"루킹삼진")+COUNTIF('타자 기록'!D2:I16,"땅볼")+COUNTIF('타자 기록'!V2:AA16,"땅볼")+COUNTIF('타자 기록'!D2:I16,"뜬공")+COUNTIF('타자 기록'!V2:AA16,"뜬공")+COUNTIF('타자 기록'!D2:I16,"직선타")+COUNTIF('타자 기록'!V2:AA16,"직선타")+COUNTIF('타자 기록'!D2:I16,"병살")+COUNTIF('타자 기록'!V2:AA16,"병살")+COUNTIF('타자 기록'!D2:I16,"실책출루")+COUNTIF('타자 기록'!V2:AA16,"실책출루")+COUNTIF('타자 기록'!D2:I16,"야수선택")+COUNTIF('타자 기록'!V2:AA16,"야수선택")+COUNTIF('타자 기록'!D2:I16,"볼넷")+COUNTIF('타자 기록'!V2:AA16,"볼넷")+COUNTIF('타자 기록'!D2:I16,"사구")+COUNTIF('타자 기록'!V2:AA16,"사구")+COUNTIF('타자 기록'!D2:I16,"희생플라이")+COUNTIF('타자 기록'!V2:AA16,"희생플라이")+COUNTIF('타자 기록'!D2:I16,"희생번트")+COUNTIF('타자 기록'!V2:AA16,"희생번트")+COUNTIF('타자 기록'!D2:I16,"낫아웃출루")+COUNTIF('타자 기록'!V2:AA16,"낫아웃출루")+COUNTIF('타자 기록'!D2:I16,"포수방해")+COUNTIF('타자 기록'!V2:AA16,"포수방해")) -> 0 | E15: =IF(OR(NOT(ISNUMBER(C15)),NOT(ISNUMBER(D15))),"",D15-C15) -> 0 | F15: =IF(C15=D15,"통과","확인 필요") -> 통과 | G15: 붙여넣기 입력도 목록과 대조
B16: 이름 없는 타자 입력 없음 | C16: =0 -> 0 | D16: =SUMPRODUCT(--('타자 기록'!B2:B16=""),'타자 기록'!AB2:AB16)+SUMIFS('타자 기록'!J2:J16,'타자 기록'!B2:B16,"")+SUMIFS('타자 기록'!K2:K16,'타자 기록'!B2:B16,"")+SUMIFS('타자 기록'!L2:L16,'타자 기록'!B2:B16,"") -> 0 | E16: =IF(OR(NOT(ISNUMBER(C16)),NOT(ISNUMBER(D16))),"",D16-C16) -> 0 | F16: =IF(C16=D16,"통과","확인 필요") -> 통과 | G16: 타자 기록 이름·타석·주루 기록
B17: 자책점 ≤ 실점 (행별) | C17: =0 -> 0 | D17: =SUMPRODUCT(--('투수 기록'!H2:H11>'투수 기록'!G2:G11)) -> 0 | E17: =IF(OR(NOT(ISNUMBER(C17)),NOT(ISNUMBER(D17))),"",D17-C17) -> 0 | F17: =IF(C17=D17,"통과","확인 필요") -> 통과 | G17: 투수 기록 G:H
B18: 피홈런 ≤ 피안타 (행별) | C18: =0 -> 0 | D18: =SUMPRODUCT(--('투수 기록'!L2:L11>'투수 기록'!F2:F11)) -> 0 | E18: =IF(OR(NOT(ISNUMBER(C18)),NOT(ISNUMBER(D18))),"",D18-C18) -> 0 | F18: =IF(C18=D18,"통과","확인 필요") -> 통과 | G18: 투수 기록 F:L
B19: 투수 필수 숫자 입력 완료 | C19: =0 -> 0 | D19: =IF('투수 기록'!A2="",0,9-COUNT('투수 기록'!C2,'투수 기록'!E2:L2))+IF('투수 기록'!A3="",0,9-COUNT('투수 기록'!C3,'투수 기록'!E3:L3))+IF('투수 기록'!A4="",0,9-COUNT('투수 기록'!C4,'투수 기록'!E4:L4))+IF('투수 기록'!A5="",0,9-COUNT('투수 기록'!C5,'투수 기록'!E5:L5))+IF('투수 기록'!A6="",0,9-COUNT('투수 기록'!C6,'투수 기록'!E6:L6))+IF('투수 기록'!A7="",0,9-COUNT('투수 기록'!C7,'투수 기록'!E7:L7))+IF('투수 기록'!A8="",0,9-COUNT('투수 기록'!C8,'투수 기록'!E8:L8))+IF('투수 기록'!A9="",0,9-COUNT('투수 기록'!C9,'투수 기록'!E9:L9))+IF('투수 기록'!A10="",0,9-COUNT('투수 기록'!C10,'투수 기록'!E10:L10))+IF('투수 기록'!A11="",0,9-COUNT('투수 기록'!C11,'투수 기록'!E11:L11)) -> 0 | E19: =IF(OR(NOT(ISNUMBER(C19)),NOT(ISNUMBER(D19))),"",D19-C19) -> 0 | F19: =IF(C19=D19,"통과","입력 대기") -> 통과 | G19: C 및 E:L = 총 9칸. 기록 없으면 0
B20: 수비 이닝 표기 유효 | C20: =1 -> 1 | D20: =IF(NOT(ISNUMBER('경기 정보'!C10)),"",IF(AND('경기 정보'!C10>=0,OR(ABS(MOD('경기 정보'!C10,1))<0.000001,ABS(MOD('경기 정보'!C10,1)-0.1)<0.000001,ABS(MOD('경기 정보'!C10,1)-0.2)<0.000001)),1,0)) -> 1 | E20: =IF(OR(NOT(ISNUMBER(C20)),NOT(ISNUMBER(D20))),"",D20-C20) -> 0 | F20: =IF(NOT(ISNUMBER(D20)),"입력 대기",IF(C20=D20,"통과","확인 필요")) -> 통과 | G20: 정수 또는 .1 / .2만 사용
B21: 플레이 판정 확인 | C21: =1 -> 1 | D21: =IF('경기 정보'!C25="확인 완료",1,0) -> 0 | E21: =IF(OR(NOT(ISNUMBER(C21)),NOT(ISNUMBER(D21))),"",D21-C21) -> -1 | F21: =IF(D21=1,"통과","확인 필요") -> 확인 필요 | G21: 안타·실책·타점·자책점
B22: 교차 기록 또는 재확인 | C22: =1 -> 1 | D22: =IF(OR('경기 정보'!C26="대조 완료",'경기 정보'!C26="1인 기록 재확인"),1,0) -> 0 | E22: =IF(OR(NOT(ISNUMBER(C22)),NOT(ISNUMBER(D22))),"",D22-C22) -> -1 | F22: =IF(D22=1,"통과","확인 필요") -> 확인 필요 | G22: 경기 정보 C26
B23: 검수 담당·완료일 입력 | C23: =4 -> 4 | D23: =COUNTA('경기 정보'!C12)+COUNTA('경기 정보'!C14:C16) -> 0 | E23: =IF(OR(NOT(ISNUMBER(C23)),NOT(ISNUMBER(D23))),"",D23-C23) -> -4 | F23: =IF(C23=D23,"통과","입력 대기") -> 입력 대기 | G23: 기록원 A / 1·2차 검수 / 완료일
B24: 3일 이내 검수·시스템 입력 | C24: =1 -> 1 | D24: =IF(OR(NOT(ISNUMBER('경기 정보'!C16)),NOT(ISNUMBER('경기 정보'!C22)),NOT(ISNUMBER('경기 정보'!C4))),"",IF(AND('경기 정보'!C16>='경기 정보'!C4,'경기 정보'!C22>='경기 정보'!C4,MAX('경기 정보'!C16,'경기 정보'!C22)<='경기 정보'!C23),1,0)) | E24: =IF(OR(NOT(ISNUMBER(C24)),NOT(ISNUMBER(D24))),"",D24-C24) | F24: =IF(NOT(ISNUMBER(D24)),"입력 대기",IF(D24=1,"통과","확인 필요")) -> 입력 대기 | G24: 완료일은 경기일 이상·경기일+3 이하
B25: 음수·소수·문자 숫자 입력 없음 | C25: =0 -> 0 | D25: =SUMPRODUCT(--('타자 기록'!J2:L16<0))+SUMPRODUCT(--('투수 기록'!C2:C11<0))+SUMPRODUCT(--('투수 기록'!E2:L11<0))+SUMPRODUCT(--(MOD(N('타자 기록'!J2:L16),1)<>0))+SUMPRODUCT(--(MOD(N('투수 기록'!C2:C11),1)<>0))+SUMPRODUCT(--(MOD(N('투수 기록'!E2:L11),1)<>0))+COUNTA('타자 기록'!J2:L16)-COUNT('타자 기록'!J2:L16)+COUNTA('투수 기록'!C2:C11)-COUNT('투수 기록'!C2:C11)+COUNTA('투수 기록'!E2:L11)-COUNT('투수 기록'!E2:L11) -> 0 | E25: =D25-C25 -> 0 | F25: =IF(D25=0,"통과","확인 필요") -> 통과 | G25: 입력 수치는 0 이상의 정수. 붙여넣기 포함.
B26: 이름 없는 투수 입력 없음 | C26: =0 -> 0 | D26: =IF('투수 기록'!A2="",COUNTA('투수 기록'!B2:C2)+COUNTA('투수 기록'!E2:L2),0)+IF('투수 기록'!A3="",COUNTA('투수 기록'!B3:C3)+COUNTA('투수 기록'!E3:L3),0)+IF('투수 기록'!A4="",COUNTA('투수 기록'!B4:C4)+COUNTA('투수 기록'!E4:L4),0)+IF('투수 기록'!A5="",COUNTA('투수 기록'!B5:C5)+COUNTA('투수 기록'!E5:L5),0)+IF('투수 기록'!A6="",COUNTA('투수 기록'!B6:C6)+COUNTA('투수 기록'!E6:L6),0)+IF('투수 기록'!A7="",COUNTA('투수 기록'!B7:C7)+COUNTA('투수 기록'!E7:L7),0)+IF('투수 기록'!A8="",COUNTA('투수 기록'!B8:C8)+COUNTA('투수 기록'!E8:L8),0)+IF('투수 기록'!A9="",COUNTA('투수 기록'!B9:C9)+COUNTA('투수 기록'!E9:L9),0)+IF('투수 기록'!A10="",COUNTA('투수 기록'!B10:C10)+COUNTA('투수 기록'!E10:L10),0)+IF('투수 기록'!A11="",COUNTA('투수 기록'!B11:C11)+COUNTA('투수 기록'!E11:L11),0) -> 0 | E26: =D26-C26 -> 0 | F26: =IF(D26=0,"통과","확인 필요") -> 통과 | G26: 투수 이름 없이 결과·숫자 입력 금지.
B27: 검수 요약 | F27: =IF(COUNTIF(F5:F26,"확인 필요")>0,"확인 필요",IF(COUNTIF(F5:F26,"입력 대기")>0,"입력 대기","검수 완료")) -> 확인 필요
B30: 1차: 숫자 대조 및 입력 누락 수정. 2차: 단장·감독의 플레이 판정·운영 해석 확인.
B31: 가능하면 2인 교차 기록, 경기 직후 대조. 경기 종료 후 3일 이내 검수·시스템 입력 완료.
B33: 수정 이력
B34: 일자 | C34: 수정자 | D34: 위치 | E34: 변경 전 / 후 | F34: 수정 근거

Sheet 경기 요약
B2: UTAH DEVILS 경기 요약
B4: 경기 정보 | C4: 값 | E4: 공격 지표 | F4: 값 | H4: 투수 지표 | I4: 값
B5: 날짜 | C5: =IF(NOT(ISNUMBER('경기 정보'!C4)),"",'경기 정보'!C4) -> 46318 | E5: PA | F5: =IF('타자 기록'!AB17=0,"",'타자 기록'!AB17) -> 32 | H5: 수비 아웃 | I5: =IF(COUNTA('투수 기록'!A2:A11)=0,"",'투수 기록'!C12) -> 21
B6: 상대팀 | C6: =IF('경기 정보'!C5="","",'경기 정보'!C5) -> 테스트팀 | E6: AB | F6: =IF('타자 기록'!AB17=0,"",'타자 기록'!M17) -> 25 | H6: 실제 이닝 | I6: =IF(COUNTA('투수 기록'!A2:A11)=0,"",'투수 기록'!D12) -> 7
B7: 홈 / 원정 | C7: =IF('경기 정보'!C6="","",'경기 정보'!C6) -> 원정 | E7: H | F7: =IF('타자 기록'!AB17=0,"",'타자 기록'!N17) -> 10 | H7: 야구 이닝 표기 | I7: =IF(COUNTA('투수 기록'!A2:A11)=0,"",'투수 기록'!R12) -> 7.0
B8: 우리 점수 | C8: =IF(NOT(ISNUMBER('경기 정보'!C8)),"",'경기 정보'!C8) -> 4 | E8: AVG | F8: =IF('타자 기록'!AB17=0,"",'타자 기록'!U17) -> 0.4 | H8: ERA | I8: =IF(COUNTA('투수 기록'!A2:A11)=0,"",'투수 기록'!M12) -> 0.71428571
B9: 상대 점수 | C9: =IF(NOT(ISNUMBER('경기 정보'!C9)),"",'경기 정보'!C9) -> 2 | E9: OBP | F9: =IF('타자 기록'!AB17=0,"",'타자 기록'!AF17) -> 0.46666667 | H9: WHIP | I9: =IF(COUNTA('투수 기록'!A2:A11)=0,"",'투수 기록'!N12) -> 1
B10: 검수·입력 마감일 | C10: =IF(NOT(ISNUMBER('경기 정보'!C23)),"",'경기 정보'!C23) -> 46321 | E10: SLG | F10: =IF('타자 기록'!AB17=0,"",'타자 기록'!AG17) -> 0.68 | H10: K/BB | I10: =IF(COUNTA('투수 기록'!A2:A11)=0,"",'투수 기록'!O12) -> 3.3333333
E11: OPS | F11: =IF('타자 기록'!AB17=0,"",'타자 기록'!AH17) -> 1.1466667 | H11: K/9 | I11: =IF(COUNTA('투수 기록'!A2:A11)=0,"",'투수 기록'!P12) -> 12.857143
B12: 경기 결과 | C12: =IF(OR(NOT(ISNUMBER('경기 정보'!C8)),NOT(ISNUMBER('경기 정보'!C9))),"입력 대기",IF('경기 정보'!C8>'경기 정보'!C9,"승",IF('경기 정보'!C8<'경기 정보'!C9,"패","무승부"))) -> 승 | E12: BB% | F12: =IF('타자 기록'!AB17=0,"",'타자 기록'!AN17) -> 0.09375 | H12: BB/9 | I12: =IF(COUNTA('투수 기록'!A2:A11)=0,"",'투수 기록'!Q12) -> 3.8571429
E13: K% | F13: =IF('타자 기록'!AB17=0,"",'타자 기록'!AO17) -> 0.15625
B15: 타격 구성
B16: 결과 | C16: 횟수 | E16: 경기 리뷰
B17: 단타 | C17: =IF('타자 기록'!AB17=0,"",'타자 기록'!AM17) -> 6
B18: 2루타 | C18: =IF('타자 기록'!AB17=0,"",'타자 기록'!O17) -> 2 | E18: 잘한 점
B19: 3루타 | C19: =IF('타자 기록'!AB17=0,"",'타자 기록'!P17) -> 1
B20: 홈런 | C20: =IF('타자 기록'!AB17=0,"",'타자 기록'!Q17) -> 1
B21: 볼넷 | C21: =IF('타자 기록'!AB17=0,"",'타자 기록'!R17) -> 3 | E21: 보완할 점
B22: 사구 | C22: =IF('타자 기록'!AB17=0,"",'타자 기록'!S17) -> 1
B23: 삼진 | C23: =IF('타자 기록'!AB17=0,"",'타자 기록'!T17) -> 5
E24: 다음 훈련
